<?xml version="1.0" encoding="utf-8"?>
<!-- This URDF was automatically created by SolidWorks to URDF Exporter! Originally created by Stephen Brawner (brawner@gmail.com) 
     Commit Version: 1.6.0-4-g7f85cfe  Build Version: 1.6.7995.38578
     For more information, please see http://wiki.ros.org/sw_urdf_exporter -->
<robot
  name="urdf_ens_v14">
  <link
    name="base_link">
    <inertial>
      <origin
        xyz="0.0045282 9.9411E-06 0.047036"
        rpy="0 0 0" />
      <mass
        value="3.7998" />
      <inertia
        ixx="0.0168"
        ixy="2.1761E-06"
        ixz="-0.00074104"
        iyy="0.015307"
        iyz="1.1367E-05"
        izz="0.026526" />
    </inertial>
    <visual>
      <origin
        xyz="0 0 0"
        rpy="0 0 0" />
      <geometry>
        <mesh
          filename="package://urdf_ens_v14/meshes/base_link.STL" />
      </geometry>
      <material
        name="">
        <color
          rgba="0.84314 0.81569 0.75294 1" />
      </material>
    </visual>
    <collision>
      <origin
        xyz="0 0 0"
        rpy="0 0 0" />
      <geometry>
        <mesh
          filename="package://urdf_ens_v14/meshes/base_link.STL" />
      </geometry>
    </collision>
  </link>
  <link
    name="arm_link_1">
    <inertial>
      <origin
        xyz="-0.010368 -5.0518E-08 0.030493"
        rpy="0 0 0" />
      <mass
        value="2.9281" />
      <inertia
        ixx="0.013631"
        ixy="-2.8231E-09"
        ixz="0.00051643"
        iyy="0.010873"
        iyz="3.8916E-08"
        izz="0.013953" />
    </inertial>
    <visual>
      <origin
        xyz="0 0 0"
        rpy="0 0 0" />
      <geometry>
        <mesh
          filename="package://urdf_ens_v14/meshes/arm_link_1.STL" />
      </geometry>
      <material
        name="">
        <color
          rgba="0 0 0 1" />
      </material>
    </visual>
    <collision>
      <origin
        xyz="0 0 0"
        rpy="0 0 0" />
      <geometry>
        <mesh
          filename="package://urdf_ens_v14/meshes/arm_link_1.STL" />
      </geometry>
    </collision>
  </link>
  <joint
    name="arm_joint_1"
    type="revolute">
    <origin
      xyz="0 -0.00035 0.14"
      rpy="0 0 0" />
    <parent
      link="base_link" />
    <child
      link="arm_link_1" />
    <axis
      xyz="0 0 -1" />
    <limit
      lower="-1.57"
      upper="1.57"
      effort="0"
      velocity="0" />
  </joint>
  <link
    name="arm_link_2">
    <inertial>
      <origin
        xyz="0.055195 -0.018875 0.00012252"
        rpy="0 0 0" />
      <mass
        value="1.4743" />
      <inertia
        ixx="0.0020004"
        ixy="0.0016708"
        ixz="2.5869E-10"
        iyy="0.0063159"
        iyz="1.0274E-09"
        izz="0.0081461" />
    </inertial>
    <visual>
      <origin
        xyz="0 0 0"
        rpy="0 0 0" />
      <geometry>
        <mesh
          filename="package://urdf_ens_v14/meshes/arm_link_2.STL" />
      </geometry>
      <material
        name="">
        <color
          rgba="0.88 0.55 0 1" />
      </material>
    </visual>
    <collision>
      <origin
        xyz="0 0 0"
        rpy="0 0 0" />
      <geometry>
        <mesh
          filename="package://urdf_ens_v14/meshes/arm_link_2.STL" />
      </geometry>
    </collision>
  </link>
  <joint
    name="arm_joint_2"
    type="revolute">
    <origin
      xyz="0 0 0.127"
      rpy="-1.5708 0 0" />
    <parent
      link="arm_link_1" />
    <child
      link="arm_link_2" />
    <axis
      xyz="0 0 1" />
    <limit
      lower="-1.22"
      upper="0.87"
      effort="0"
      velocity="0" />
  </joint>
  <link
    name="arm_link_3">
    <inertial>
      <origin
        xyz="0.080238 0.019929 -0.0045918"
        rpy="0 0 0" />
      <mass
        value="0.49873" />
      <inertia
        ixx="0.00024822"
        ixy="-0.00025317"
        ixz="4.3983E-06"
        iyy="0.0012034"
        iyz="1.1183E-06"
        izz="0.0014147" />
    </inertial>
    <visual>
      <origin
        xyz="0 0 0"
        rpy="0 0 0" />
      <geometry>
        <mesh
          filename="package://urdf_ens_v14/meshes/arm_link_3.STL" />
      </geometry>
      <material
        name="">
        <color
          rgba="0.88 0.1 0.1 1" />
      </material>
    </visual>
    <collision>
      <origin
        xyz="0 0 0"
        rpy="0 0 0" />
      <geometry>
        <mesh
          filename="package://urdf_ens_v14/meshes/arm_link_3.STL" />
      </geometry>
    </collision>
  </link>
  <joint
    name="arm_joint_3"
    type="revolute">
    <origin
      xyz="0.18451 -0.063087 0.04904"
      rpy="0 0 0" />
    <parent
      link="arm_link_2" />
    <child
      link="arm_link_3" />
    <axis
      xyz="0 0 1" />
    <limit
      lower="-1.74"
      upper="1.22"
      effort="0"
      velocity="0" />
  </joint>
  <link
    name="arm_link_4">
    <inertial>
      <origin
        xyz="0.049693 -0.064958 -0.021851"
        rpy="0 0 0" />
      <mass
        value="0.31791" />
      <inertia
        ixx="0.00015589"
        ixy="4.0119E-05"
        ixz="-1.8787E-07"
        iyy="0.00010992"
        iyz="-6.522E-07"
        izz="0.00011596" />
    </inertial>
    <visual>
      <origin
        xyz="0 0 0"
        rpy="0 0 0" />
      <geometry>
        <mesh
          filename="package://urdf_ens_v14/meshes/arm_link_4.STL" />
      </geometry>
      <material
        name="">
        <color
          rgba="0.11 0.11 0.88 1" />
      </material>
    </visual>
    <collision>
      <origin
        xyz="0 0 0"
        rpy="0 0 0" />
      <geometry>
        <mesh
          filename="package://urdf_ens_v14/meshes/arm_link_4.STL" />
      </geometry>
    </collision>
  </link>
  <joint
    name="arm_joint_4"
    type="revolute">
    <origin
      xyz="0.19396 0.048233 -0.03012"
      rpy="-3.1416 0 0" />
    <parent
      link="arm_link_3" />
    <child
      link="arm_link_4" />
    <axis
      xyz="0 0 -1" />
    <limit
      lower="-1.22"
      upper="1.04"
      effort="0"
      velocity="0" />
  </joint>

  <transmission name ="trans_1">
    <type>transmission_interface/SimpleTransmission</type>
    <joint name="arm_joint_1">
        <hardwareInterface>hardware_interface/PositionJointInterface</hardwareInterface>
    </joint>
    <actuator name="motor_1">
        <hardwareInterface>hardware_interface/PositionJointInterface</hardwareInterface>
        <mechanicalReduction>1</mechanicalReduction>
    </actuator>
</transmission>

<transmission name ="trans_2">
    <type>transmission_interface/SimpleTransmission</type>
    <joint name="arm_joint_2">
        <hardwareInterface>hardware_interface/PositionJointInterface</hardwareInterface>
    </joint>
    <actuator name="motor_2">
        <hardwareInterface>hardware_interface/PositionJointInterface</hardwareInterface>
        <mechanicalReduction>1</mechanicalReduction>
    </actuator>
</transmission>
<transmission name ="trans_3">
    <type>transmission_interface/SimpleTransmission</type>
    <joint name="arm_joint_3">
        <hardwareInterface>hardware_interface/PositionJointInterface</hardwareInterface>
    </joint>
    <actuator name="motor_3">
        <hardwareInterface>hardware_interface/PositionJointInterface</hardwareInterface>
        <mechanicalReduction>1</mechanicalReduction>
    </actuator>
</transmission>
<transmission name ="trans_4">
    <type>transmission_interface/SimpleTransmission</type>
    <joint name="arm_joint_4">
        <hardwareInterface>hardware_interface/PositionJointInterface</hardwareInterface>
    </joint>
    <actuator name="motor_4">
        <hardwareInterface>hardware_interface/PositionJointInterface</hardwareInterface>
        <mechanicalReduction>1</mechanicalReduction>
    </actuator>
</transmission>
</robot>